#include <iostream>
#include <vector>

// Mock the CUDA dependencies for testing
typedef struct {} curandState;
struct GPUNeuronState {};
struct GPUSynapse {};
struct GPUCorticalColumn { 
    int neuron_start, neuron_end, synapse_start, synapse_end;
    float* d_local_dopamine;
    curandState* d_local_rng_state;
};

// Include NetworkConfig
#include <NeuroGen/NetworkConfig.h>

// Now include NetworkCUDA but skip the CUDA-specific parts
#define __global__
#define __device__
#define cudaStream_t int
#define cudaError_t int
#define cudaSuccess 0

#include <NeuroGen/cuda/NetworkCUDA.cuh>

int main() {
    std::cout << "Testing NetworkCUDA class definition..." << std::endl;
    
    try {
        // Create a basic network config  
        NetworkConfig config;
        config.numColumns = 4;
        config.neuronsPerColumn = 10;
        config.localFanOut = 5;
        
        // Test NetworkConfigCUDA
        NetworkConfigCUDA cuda_config(config);
        cuda_config.enable_cuda = true;
        cuda_config.threads_per_block = 256;
        
        std::cout << "NetworkConfigCUDA created successfully!" << std::endl;
        std::cout << cuda_config.toString() << std::endl;
        
        // Test class instantiation (constructor)
        NetworkCUDA network(cuda_config);
        
        std::cout << "NetworkCUDA class instantiated successfully!" << std::endl;
        
        // Test basic getters (these should work without CUDA initialization)
        std::cout << "Number of neurons: " << network.getNumNeurons() << std::endl;
        std::cout << "Number of synapses: " << network.getNumSynapses() << std::endl;
        
        // Test error handling
        try {
            NetworkException test_exception(NetworkError::CUDA_ERROR, "Test error");
            std::cout << "NetworkException: " << test_exception.what() << std::endl;
        } catch (const std::exception& e) {
            std::cout << "Caught exception: " << e.what() << std::endl;
        }
        
        std::cout << "All tests passed! NetworkCUDA class is properly defined." << std::endl;
        return 0;
        
    } catch (const std::exception& e) {
        std::cout << "Error: " << e.what() << std::endl;
        return 1;
    }
}
